package Excepions;

import java.util.Scanner;

class Alpha{
	public void division() throws  ArithmeticException{
		try {
		Scanner scan = new Scanner(System.in);
		System.out.println("enter the first number to divide");
		int a = scan.nextInt();
		System.out.println("enter the next number");
		int b = scan.nextInt();
		int res = a / b;
		System.out.println("The result is " + res);
		System.out.println("thanks for using application");
		}
		catch(ArithmeticException e) {
			System.out.println("handling in division method");
		}
	}
}
public class RethrowException {
	public static void main(String[] args) {
		Alpha a  =new Alpha();
		a.division();
	}

}
