package Excepions;

import java.util.Scanner;

class Alpha{
	public void division() {
		Scanner scan = new Scanner(System.in);
		System.out.println("enter the first number to divide");
		int a = scan.nextInt();
		System.out.println("enter the next number");
		int b = scan.nextInt();
		int res = a / b;
		System.out.println("The result is " + res);
		System.out.println("thanks for using application");
	}
}
class Beta{
	public void display() {
		Alpha a  =new Alpha();
		a.division();
	}
}
public class Exception3 {
public static void main(String[] args) {
	Beta b =new Beta();
	try {
	b.display();
	}
	catch(ArithmeticException e){
		System.out.println("handling in Main method");
	}
	
}
}
