package Excepions;

import java.util.Scanner;

class Alpha1{
	public void division() throws  ArithmeticException{
		try {
		Scanner scan = new Scanner(System.in);
		System.out.println("enter the first number to divide");
		int a = scan.nextInt();
		System.out.println("enter the next number");
		int b = scan.nextInt();
		int res = a / b;
		System.out.println("The result is " + res);
		System.out.println("thanks for using application");
		}
		catch(ArithmeticException e) {
			System.out.println("handling in division method");
			throw e; //rethrowing an error
		}
	}
}
public class RethrowException {
	public static void main(String[] args) {
		Alpha1 a  =new Alpha1();
		try {
		a.division();
		}
		catch(ArithmeticException e){
			System.out.println("handled in main method");
		}
	}

}
